Workbook

Sheet Summary
A1: AquaSentinel R3: costed bill of materials (23 Oct 2026)
A2: Every price is ex-GST unless the row says otherwise. Basis and source for every line are on the Costed BOM sheet.
A4: Subsystem | B4: Prototype (1 unit) | C4: At 100 units
A5: Sensors | B5: =SUMIF('Costed BOM'!$A$2:$A$80,A5,'Costed BOM'!$F$2:$F$80) -> 69001.25 | C5: =SUMIF('Costed BOM'!$A$2:$A$80,A5,'Costed BOM'!$H$2:$H$80) -> 58690.85
A6: Electronics | B6: =SUMIF('Costed BOM'!$A$2:$A$80,A6,'Costed BOM'!$F$2:$F$80) -> 11484 | C6: =SUMIF('Costed BOM'!$A$2:$A$80,A6,'Costed BOM'!$H$2:$H$80) -> 8224
A7: Power | B7: =SUMIF('Costed BOM'!$A$2:$A$80,A7,'Costed BOM'!$F$2:$F$80) -> 3322.26 | C7: =SUMIF('Costed BOM'!$A$2:$A$80,A7,'Costed BOM'!$H$2:$H$80) -> 2757.85
A8: Actuators | B8: =SUMIF('Costed BOM'!$A$2:$A$80,A8,'Costed BOM'!$F$2:$F$80) -> 5602.56 | C8: =SUMIF('Costed BOM'!$A$2:$A$80,A8,'Costed BOM'!$H$2:$H$80) -> 5602.56
A9: Sampler | B9: =SUMIF('Costed BOM'!$A$2:$A$80,A9,'Costed BOM'!$F$2:$F$80) -> 1849.84 | C9: =SUMIF('Costed BOM'!$A$2:$A$80,A9,'Costed BOM'!$H$2:$H$80) -> 1849.84
A10: Fabricated parts | B10: =SUMIF('Costed BOM'!$A$2:$A$80,A10,'Costed BOM'!$F$2:$F$80) -> 76172.17 | C10: =SUMIF('Costed BOM'!$A$2:$A$80,A10,'Costed BOM'!$H$2:$H$80) -> 53462.7
A11: Bought mechanical | B11: =SUMIF('Costed BOM'!$A$2:$A$80,A11,'Costed BOM'!$F$2:$F$80) -> 2050 | C11: =SUMIF('Costed BOM'!$A$2:$A$80,A11,'Costed BOM'!$H$2:$H$80) -> 1950
A12: Fasteners | B12: =SUMIF('Costed BOM'!$A$2:$A$80,A12,'Costed BOM'!$F$2:$F$80) -> 5190 | C12: =SUMIF('Costed BOM'!$A$2:$A$80,A12,'Costed BOM'!$H$2:$H$80) -> 5190
A13: Assembly & test | B13: =SUMIF('Costed BOM'!$A$2:$A$80,A13,'Costed BOM'!$F$2:$F$80) -> 6600 | C13: =SUMIF('Costed BOM'!$A$2:$A$80,A13,'Costed BOM'!$H$2:$H$80) -> 4800
A14: Freight and tooling (contingency is in the pilot budget) | B14: ='Costed BOM'!F83+'Costed BOM'!F84+'Costed BOM'!F85 -> 5438.1624 | C14: ='Costed BOM'!H83+'Costed BOM'!H84+'Costed BOM'!H85 -> 5525.834
A15: Float + bridge kit, ex-GST | B15: ='Costed BOM'!F86 -> 186710.24 | C15: ='Costed BOM'!H86 -> 148053.63
A16: Cash cost incl. 18 % GST | B16: ='Costed BOM'!F88 -> 220318.09 | C16: ='Costed BOM'!H88 -> 174703.29
A17: of which the bridge mount kit (once per site) | B17: =SUMIF('Costed BOM'!$M$2:$M$80,"Site kit",'Costed BOM'!$F$2:$F$80)*(1+0.03) -> 29217.711 | C17: =SUMIF('Costed BOM'!$M$2:$M$80,"Site kit",'Costed BOM'!$H$2:$H$80)*(1+0.03) -> 24309.267
A18: of which the float | B18: =B15-B17 -> 157492.53 | C18: =C15-C17 -> 123744.37
A20: Value engineering, 23 Oct 2026 (design changes to confirm in CAD) | B20: Saving, prototype | C20: Saving at 100
A21: AS3-101 Pier bracket (weldment) - upper and lower identical | B21: 5708 | C21: 5448
A22: AS3-102 Pole clamp cap | B22: 3903 | C22: 3855
A23: AS3-113 Stop collar: bought 2-inch stainless clamp collar | B23: 2778 | C23: 2169
A24: AS3-301 Guide carriage - fixed half (weldment) | B24: 268 | C24: 268
A25: AS3-302 Guide carriage - opening gate (weldment) | B25: 183 | C25: 183
A26: Contingency counted once (now only in the pilot budget), and freight on the cut parts | B26: 19798
A27: Before these changes: float + mount together, prototype | B27: 219348 | C27: 168059
A29: Part count (verified from mechanical/cad/BOM_R3.csv)
A30: Unique part numbers | B30: 66
A31: Physical pieces | B31: 144
A32: Fabricated parts (part numbers) | B32: 34
A33: Bought-in parts | B33: 20
A34: Fastener types (51 pieces) | B34: 9
A35: Harness sets | B35: 3
A36: SOLIDWORKS files in the Pack and Go (66 parts + 1 assembly) | B36: 67
A38: Previous team cost sheet (v2 layout, mixed GST) | B38: 138000 | C38: sum of its lines
A39: Previous sheet's own 'at 100 units' column | B39: 90576 | C39: $943.50 TOTAL row x ₹96

Sheet Costed BOM
A1: Group | B1: Part no. | C1: Item | D1: Qty | E1: Unit cost, prototype (₹ ex-GST) | F1: Extended, prototype | G1: Unit cost at 100 units | H1: Extended at 100 units | I1: Basis | J1: Source id | K1: How the price was found | L1: At 100 units | M1: Float or site kit
A2: Sensors | B2: AS3-420 | C2: pH probe, DFRobot SEN0708 (RS485, IP68) | D2: 1 | E2: 12384 | F2: =D2*E2 -> 12384 | G2: 10526.4 | H2: =D2*G2 -> 10526.4 | I2: LISTED | J2: S1, S4, S5 | K2: $129 x Rs 96/$ (Evelta's own INR pricing) | L2: ASSUMPTION: 15 % volume / direct-import discount | M2: Float
A3: Sensors | B3: AS3-420 | C3: EC probe K=10, DFRobot SEN0707 (RS485, IP68) | D3: 1 | E3: 15264 | F3: =D3*E3 -> 15264 | G3: 12974.4 | H3: =D3*G3 -> 12974.4 | I3: LISTED | J3: S2, S4, S5 | K3: $159 x Rs 96/$ (Evelta's own INR pricing) | L3: ASSUMPTION: 15 % volume / direct-import discount | M3: Float
A4: Sensors | B4: AS3-420 | C4: Optical DO probe, DFRobot SEN0680 (RS485, IP68) | D4: 1 | E4: 19104 | F4: =D4*E4 -> 19104 | G4: 16238.4 | H4: =D4*G4 -> 16238.4 | I4: LISTED | J4: S1, S4, S5 | K4: $199 x Rs 96/$ (Evelta's own INR pricing) | L4: ASSUMPTION: 15 % volume / direct-import discount | M4: Float
A5: Sensors | B5: AS3-420 | C5: Turbidity probe 0-1000 NTU, DFRobot SEN0710 (RS485) | D5: 1 | E5: 21984 | F5: =D5*E5 -> 21984 | G5: 18686.4 | H5: =D5*G5 -> 18686.4 | I5: LISTED | J5: S3, S4, S5 | K5: $229 x Rs 96/$ (Evelta's own INR pricing) | L5: ASSUMPTION: 15 % volume / direct-import discount | M5: Float
A6: Sensors | B6: AS3-712 | C6: River-level sensor JSN-SR04T (waterproof ultrasonic) | D6: 1 | E6: 265.25 | F6: =D6*E6 -> 265.25 | G6: 265.25 | H6: =D6*G6 -> 265.25 | I6: LISTED | J6: S7 | M6: Float
A7: Electronics | B7: AS3-515 | C7: ESP32-WROOM-32E (DevKitC for the prototype) | D7: 1 | E7: 749 | F7: =D7*E7 -> 749 | G7: 350 | H7: =D7*G7 -> 350 | I7: LISTED | J7: S8 | L7: ASSUMPTION: bare WROOM-32E module on our own board | M7: Float
A8: Electronics | B8: AS3-515 | C8: LTE Cat-1 modem SIMCom A7670C (on carrier board) | D8: 1 | E8: 1900 | F8: =D8*E8 -> 1900 | G8: 489 | H8: =D8*G8 -> 489 | I8: LISTED | J8: S9 | K8: carrier with regulator | L8: LISTED S9: bare A7670C-LNNV module | M8: Float
A9: Electronics | B9: AS3-515 | C9: RS485 transceiver MAX3485 | D9: 1 | E9: 325 | F9: =D9*E9 -> 325 | G9: 325 | H9: =D9*G9 -> 325 | I9: LISTED | J9: S19 | K9: genuine IC, Evelta | M9: Float
A10: Electronics | B10: AS3-515 | C10: Real-time clock DS3231 module | D10: 1 | E10: 105 | F10: =D10*E10 -> 105 | G10: 105 | H10: =D10*G10 -> 105 | I10: LISTED | J10: S19 | M10: Float
A11: Electronics | B11: AS3-515 | C11: Power monitor INA226 module | D11: 1 | E11: 285 | F11: =D11*E11 -> 285 | G11: 285 | H11: =D11*G11 -> 285 | I11: LISTED | J11: S19 | M11: Float
A12: Electronics | B12: AS3-515 | C12: PWM driver PCA9685 module (beacon, wiper, valve) | D12: 1 | E12: 300 | F12: =D12*E12 -> 300 | G12: 300 | H12: =D12*G12 -> 300 | I12: ASSUMPTION | K12: no Indian listing found | M12: Float
A13: Electronics | B13: AS3-515 | C13: microSD socket + 16 GB industrial card | D13: 1 | E13: 510 | F13: =D13*E13 -> 510 | G13: 510 | H13: =D13*G13 -> 510 | I13: ASSUMPTION | M13: Float
A14: Electronics | B14: AS3-515 | C14: Buck converters 3.3 V / 4.0 V / 5 V | D14: 3 | E14: 150 | F14: =D14*E14 -> 450 | G14: 150 | H14: =D14*G14 -> 450 | I14: ASSUMPTION | K14: LM2596/MP1584 class modules | M14: Float
A15: Electronics | B15: AS3-515 | C15: MOSFET load switches, TVS, fuse, connectors, passives | D15: 1 | E15: 600 | F15: =D15*E15 -> 600 | G15: 600 | H15: =D15*G15 -> 600 | I15: ASSUMPTION | M15: Float
A16: Electronics | B16: AS3-515 | C16: Carrier PCB, 2-layer (5 boards incl. shipping) | D16: 1 | E16: 2100 | F16: =D16*E16 -> 2100 | G16: 650 | H16: =D16*G16 -> 650 | I16: DERIVED | J16: S21 | K16: $2 boards + about $20 courier | L16: ASSUMPTION: Rs 150 board + Rs 500 SMT assembly | M16: Float
A17: Electronics | B17: AS3-511 | C17: IP67 polycarbonate enclosure (pod body + lid) | D17: 1 | E17: 1500 | F17: =D17*E17 -> 1500 | G17: 1500 | H17: =D17*G17 -> 1500 | I17: LISTED | J17: S18 | M17: Float
A18: Electronics | B18: AS3-811 | C18: IP68 cable glands M16 | D18: 10 | E18: 70 | F18: =D18*E18 -> 700 | G18: 70 | H18: =D18*G18 -> 700 | I18: DERIVED | J18: S22 | K18: SGD 1.00 x about Rs 70 | M18: Float
A19: Electronics | B19: AS3-711 | C19: 4G LTE antenna + IP67 bulkhead pigtail | D19: 1 | E19: 560 | F19: =D19*E19 -> 560 | G19: 560 | H19: =D19*G19 -> 560 | I19: DERIVED | J19: S17 | K19: Rs 160 antenna + Rs 400 bulkhead (assumption) | M19: Float
A20: Electronics | B20: AS3-811 | C20: Marine cable harness (15 m) + connectors | D20: 1 | E20: 1400 | F20: =D20*E20 -> 1400 | G20: 1400 | H20: =D20*G20 -> 1400 | I20: ASSUMPTION | M20: Float
A21: Power | B21: AS3-514 | C21: LiFePO4 12.8 V 6 Ah with BMS | D21: 1 | E21: 1864.41 | F21: =D21*E21 -> 1864.41 | G21: 1300 | H21: =D21*G21 -> 1300 | I21: LISTED | J21: S10 | K21: Rs 2,200 incl. GST | L21: LISTED S10: IndiaMART Rs 1,300 | M21: Float
A22: Power | B22: AS3-521 | C22: Solar panel 20 W, 12 V | D22: 1 | E22: 1100.85 | F22: =D22*E22 -> 1100.85 | G22: 1100.85 | H22: =D22*G22 -> 1100.85 | I22: LISTED | J22: S11 | K22: Rs 1,299 incl. GST | M22: Float
A23: Power | B23: AS3-516 | C23: MPPT solar charger CN3791 (set to 14.4 V for LiFePO4) | D23: 1 | E23: 207 | F23: =D23*E23 -> 207 | G23: 207 | H23: =D23*G23 -> 207 | I23: LISTED | J23: S12 | K23: feedback divider changed for LiFePO4 | M23: Float
A24: Power | B24: AS3-516 | C24: Battery fuse, holder and isolator | D24: 1 | E24: 150 | F24: =D24*E24 -> 150 | G24: 150 | H24: =D24*G24 -> 150 | I24: ASSUMPTION | M24: Float
A25: Actuators | B25: AS3-606 | C25: Peristaltic pump 12 V, 260 mL/min (Kamoer KPHM200) | D25: 1 | E25: 1590.68 | F25: =D25*E25 -> 1590.68 | G25: 1590.68 | H25: =D25*G25 -> 1590.68 | I25: LISTED | J25: S13 | K25: design note: 250 mL fill takes about 58 s instead of 30 s | M25: Float
A26: Actuators | B26: AS3-606 | C26: Solenoid valves 12 V (sample / purge-to-waste) | D26: 2 | E26: 505.08 | F26: =D26*E26 -> 1010.16 | G26: 505.08 | H26: =D26*G26 -> 1010.16 | I26: LISTED | J26: S14 | K26: two 2-way valves replace one 3-way pinch valve | M26: Float
A27: Actuators | B27: AS3-603 | C27: Carousel drive: N20 12 V gear motor | D27: 1 | E27: 189 | F27: =D27*E27 -> 189 | G27: 189 | H27: =D27*G27 -> 189 | I27: LISTED | J27: S20 | M27: Float
A28: Actuators | B28: AS3-603 | C28: Carousel index sensor (optical slot) + bearing | D28: 1 | E28: 280 | F28: =D28*E28 -> 280 | G28: 280 | H28: =D28*G28 -> 280 | I28: ASSUMPTION | M28: Float
A29: Actuators | B29: AS3-411 | C29: Wiper servo, metal gear, waterproof (RDS3218) | D29: 1 | E29: 1009 | F29: =D29*E29 -> 1009 | G29: 1009 | H29: =D29*G29 -> 1009 | I29: LISTED | J29: S15 | K29: IP66; sealed inside the IP68 cartridge cap | M29: Float
A30: Actuators | B30: AS3-703 | C30: Beacon: 12 V waterproof LED strobes, green + red | D30: 2 | E30: 761.86 | F30: =D30*E30 -> 1523.72 | G30: 761.86 | H30: =D30*G30 -> 1523.72 | I30: LISTED | J30: S16 | M30: Float
A31: Sampler | B31: AS3-604 | C31: Sample bottles, 250 mL HDPE wide mouth | D31: 4 | E31: 72.46 | F31: =D31*E31 -> 289.84 | G31: 72.46 | H31: =D31*G31 -> 289.84 | I31: LISTED | J31: S23 | K31: Tarsons, mid of Rs 75-96 incl. GST | M31: Float
A32: Sampler | B32: AS3-605 | C32: Septum caps | D32: 4 | E32: 30 | F32: =D32*E32 -> 120 | G32: 30 | H32: =D32*G32 -> 120 | I32: ASSUMPTION | M32: Float
A33: Sampler | B33: AS3-812 | C33: Food-grade tubing (intake, purge) | D33: 3 | E33: 80 | F33: =D33*E33 -> 240 | G33: 80 | H33: =D33*G33 -> 240 | I33: ASSUMPTION | K33: Rs per metre | M33: Float
A34: Sampler | B34: AS3-601 | C34: Insulated sampler cassette + lid (bought cool box, modified) | D34: 1 | E34: 1200 | F34: =D34*E34 -> 1200 | G34: 1200 | H34: =D34*G34 -> 1200 | I34: ASSUMPTION | M34: Float
A35: Fabricated parts | B35: AS3-101 | C35: Pier bracket (weldment) - upper and lower identical | D35: 2 | E35: 6403.88 | F35: =D35*E35 -> 12807.76 | G35: 4853.88 | H35: =D35*G35 -> 9707.76 | I35: DERIVED | J35: S25, S29-S32 | K35: 6.35 kg x 1.3 x Rs 315/kg + labour + finish; laser-cut 6 mm 316L, TIG welded (VE: was 10/12 mm) | L35: bulk material -5 %, labour -40 % (assumption) | M35: Site kit
A36: Fabricated parts | B36: AS3-102 | C36: Pole clamp cap | D36: 2 | E36: 1639.4 | F36: =D36*E36 -> 3278.8 | G36: 1174.83 | H36: =D36*G36 -> 2349.66 | I36: DERIVED | J36: S25, S29-S32 | K36: 1.20 kg x 1.3 x Rs 315/kg + labour + finish; laser-cut 316L strap clamp (VE: was machined from bar) | L36: bulk material -5 %, labour -40 % (assumption) | M36: Site kit
A37: Fabricated parts | B37: AS3-103 | C37: Stage target plate | D37: 1 | E37: 679.97 | F37: =D37*E37 -> 679.97 | G37: 480.64 | H37: =D37*G37 -> 480.64 | I37: DERIVED | J37: S25, S29-S32 | K37: 0.46 kg x 1.3 x Rs 315/kg + labour + finish; welded to the clamp cap | L37: bulk material -5 %, labour -40 % (assumption) | M37: Site kit
A38: Fabricated parts | B38: AS3-111 | C38: Guide pole 2in Sch 40S SS316L | D38: 1 | E38: 7690.18 | F38: =D38*E38 -> 7690.18 | G38: 7253.17 | H38: =D38*G38 -> 7253.17 | I38: DERIVED | J38: S24, S29-S32 | K38: 16.41 kg x 1.05 x Rs 438/kg + labour + finish; 2 in Sch 40S 316L, cut and deburred | L38: bulk material -5 %, labour -40 % (assumption) | M38: Site kit
A39: Fabricated parts | B39: AS3-211 | C39: Crossbeam SHS 40x40x3 | D39: 4 | E39: 796.53 | F39: =D39*E39 -> 3186.12 | G39: 742.56 | H39: =D39*G39 -> 2970.24 | I39: DERIVED | J39: S26, S29-S32 | K39: 0.87 kg x 1.1 x Rs 375/kg + labour + finish; saw-cut, drilled SHS | L39: bulk material -5 %, labour -40 % (assumption) | M39: Float
A40: Fabricated parts | B40: AS3-213 | C40: Equipment deck plate | D40: 1 | E40: 4413.47 | F40: =D40*E40 -> 4413.47 | G40: 3304.97 | H40: =D40*G40 -> 3304.97 | I40: DERIVED | J40: S26, S29-S32 | K40: 1.99 kg x 1.3 x Rs 375/kg + labour + finish; laser-cut tread plate | L40: bulk material -5 %, labour -40 % (assumption) | M40: Float
...

Sheet Fabricated parts
A1: Part no. | B1: Part | C1: Qty | D1: CAD mass each (kg) | E1: Material rate (₹/kg) | F1: Buy factor | G1: Material (₹) | H1: Laser cut (m) | I1: TIG (h) | J1: CNC (h) | K1: Fitting (h) | L1: Labour (₹) | M1: Finish (₹) | N1: Bought extras (₹) | O1: Unit cost (₹) | P1: Process
A2: AS3-101 | B2: Pier bracket (weldment) - upper and lower identical | C2: 2 | D2: 6.349 | E2: 315 | F2: 1.3 | G2: =D2*F2*E2 -> 2599.9155 | H2: 4 | I2: 2 | J2: 0 | K2: 0.5 | L2: =H2*500+I2*700+J2*450+K2*300 -> 3550 | M2: 253.96 | N2: 0 | O2: =G2+L2+M2+N2 -> 6403.8755 | P2: laser-cut 6 mm 316L, TIG welded (VE: was 10/12 mm)
A3: AS3-102 | B3: Pole clamp cap | C3: 2 | D3: 1.2 | E3: 315 | F3: 1.3 | G3: =D3*F3*E3 -> 491.4 | H3: 1.5 | I3: 0.5 | J3: 0 | K3: 0 | L3: =H3*500+I3*700+J3*450+K3*300 -> 1100 | M3: 48 | N3: 0 | O3: =G3+L3+M3+N3 -> 1639.4 | P3: laser-cut 316L strap clamp (VE: was machined from bar)
A4: AS3-103 | B4: Stage target plate | C4: 1 | D4: 0.456 | E4: 315 | F4: 1.3 | G4: =D4*F4*E4 -> 186.732 | H4: 0.6 | I4: 0.25 | J4: 0 | K4: 0 | L4: =H4*500+I4*700+J4*450+K4*300 -> 475 | M4: 18.24 | N4: 0 | O4: =G4+L4+M4+N4 -> 679.972 | P4: welded to the clamp cap
A5: AS3-111 | B5: Guide pole 2in Sch 40S SS316L | C5: 1 | D5: 16.414 | E5: 437.5 | F5: 1.05 | G5: =D5*F5*E5 -> 7540.1813 | H5: 0 | I5: 0 | J5: 0 | K5: 0.5 | L5: =H5*500+I5*700+J5*450+K5*300 -> 150 | M5: 0 | N5: 0 | O5: =G5+L5+M5+N5 -> 7690.1813 | P5: 2 in Sch 40S 316L, cut and deburred
A6: AS3-211 | B6: Crossbeam SHS 40x40x3 | C6: 4 | D6: 0.871 | E6: 375 | F6: 1.1 | G6: =D6*F6*E6 -> 359.2875 | H6: 0 | I6: 0 | J6: 0 | K6: 0.3 | L6: =H6*500+I6*700+J6*450+K6*300 -> 90 | M6: 347.24 | N6: 0 | O6: =G6+L6+M6+N6 -> 796.5275 | P6: saw-cut, drilled SHS
A7: AS3-213 | B7: Equipment deck plate | C7: 1 | D7: 1.99 | E7: 375 | F7: 1.3 | G7: =D7*F7*E7 -> 970.125 | H7: 5 | I7: 0 | J7: 0 | K7: 0.5 | L7: =H7*500+I7*700+J7*450+K7*300 -> 2650 | M7: 793.35 | N7: 0 | O7: =G7+L7+M7+N7 -> 4413.475 | P7: laser-cut tread plate
A8: AS3-301 | B8: Guide carriage - fixed half (weldment) | C8: 1 | D8: 2.806 | E8: 375 | F8: 1.4 | G8: =D8*F8*E8 -> 1473.15 | H8: 6 | I8: 3 | J8: 0 | K8: 1 | L8: =H8*500+I8*700+J8*450+K8*300 -> 5400 | M8: 610.18 | N8: 0 | O8: =G8+L8+M8+N8 -> 7483.33 | P8: laser-cut, TIG-welded carriage (VE: standard anodising)
A9: AS3-302 | B9: Guide carriage - opening gate (weldment) | C9: 1 | D9: 1.914 | E9: 375 | F9: 1.4 | G9: =D9*F9*E9 -> 1004.85 | H9: 4 | I9: 2 | J9: 0 | K9: 0.5 | L9: =H9*500+I9*700+J9*450+K9*300 -> 3550 | M9: 416.21 | N9: 0 | O9: =G9+L9+M9+N9 -> 4971.06 | P9: carriage gate (VE: standard anodising)
A10: AS3-311 | B10: Concave guide roller UHMW-PE | C10: 8 | D10: 0.057 | E10: 380 | F10: 2.5 | G10: =D10*F10*E10 -> 54.15 | H10: 0 | I10: 0 | J10: 0.5 | K10: 0 | L10: =H10*500+I10*700+J10*450+K10*300 -> 225 | M10: 0 | N10: 0 | O10: =G10+L10+M10+N10 -> 279.15 | P10: CNC-turned concave roller
A11: AS3-313 | B11: Gate hinge pin D10 | C11: 1 | D11: 0.189 | E11: 437.5 | F11: 2 | G11: =D11*F11*E11 -> 165.375 | H11: 0 | I11: 0 | J11: 0.5 | K11: 0 | L11: =H11*500+I11*700+J11*450+K11*300 -> 225 | M11: 0 | N11: 0 | O11: =G11+L11+M11+N11 -> 390.375 | P11: hinge pin
A12: AS3-314 | B12: T-handle latch pin (tool-free) | C12: 2 | D12: 0.072 | E12: 437.5 | F12: 1.5 | G12: =D12*F12*E12 -> 47.25 | H12: 0 | I12: 0.5 | J12: 0 | K12: 0 | L12: =H12*500+I12*700+J12*450+K12*300 -> 350 | M12: 0 | N12: 0 | O12: =G12+L12+M12+N12 -> 397.25 | P12: T-handle latch pin
A13: AS3-321 | B13: Carriage brace struts (pair) | C13: 1 | D13: 0.85 | E13: 437.5 | F13: 1.2 | G13: =D13*F13*E13 -> 446.25 | H13: 0 | I13: 0 | J13: 0 | K13: 1 | L13: =H13*500+I13*700+J13*450+K13*300 -> 300 | M13: 34 | N13: 0 | O13: =G13+L13+M13+N13 -> 780.25 | P13: 316L tube struts
... A28: AS3-801 | B28: Grab handle (two-person carry) | C28: 4 | D28: 0.23 | E28: 437.5 | F28: 1.2 | G28: =D28*F28*E28 -> 120.75 | H28: 0 | I28: 0.5 | J28: 0 | K28: 0 | L28: =H28*500+I28*700+J28*450+K28*300 -> 350 | M28: 9.2 | N28: 0 | O28: =G28+L28+M28+N28 -> 479.95 | P28: grab handle
B30: Labour rates: laser cutting ₹500/m (S29), TIG ₹700/h (S30), CNC ₹450/h (S31), fitting ₹300/h (S30). Finish: passivation ₹40/kg (assumption); anodising ₹150/sq ft, hard anodising ₹216/sq ft (S32), area from mass, density and wall thickness. Buy factor covers offcuts and machining stock.

Sheet R3 BOM check
A1: Part no. | B1: Description (BOM_R3.csv) | C1: Qty | D1: Type | E1: Material | F1: Process | G1: CAD mass each (kg) | H1: Costed as
A2: AS3-101 | B2: Pier bracket (weldment) - upper and lower identical | C2: 2 | D2: part | E2: Stainless steel 316L | F2: Laser-cut 316L 10/12 mm, TIG welded, passivated; 4x M12 chemical anchors | G2: 12.698 | H2: Pier bracket (weldment) - upper and lower identical
A3: AS3-102 | B3: Pole clamp cap | C3: 2 | D3: part | E3: Stainless steel 316L | F3: Machined 316L | G3: 2.941 | H3: Pole clamp cap
A4: AS3-103 | B4: Stage target plate | C4: 1 | D4: part | E4: Stainless steel 316L | F4: 4 mm 316L welded to the upper clamp cap | G4: 0.456 | H4: Stage target plate
A5: AS3-111 | B5: Guide pole 2in Sch 40S SS316L | C5: 1 | D5: part | E5: Stainless steel 316L | F5: ASTM A312 TP316L pipe, cut to length, ends deburred | G5: 16.414 | H5: Guide pole 2in Sch 40S SS316L
A6: AS3-112 | B6: Pole top cap | C6: 1 | D6: purchased | E6: Acetal (POM) black | G6: 0.124 | H6: Pole top cap (POM)
A7: AS3-113 | B7: Stop collar (split, clamp-on) | C7: 2 | D7: part | E7: Stainless steel 316L | F7: Machined 316L, M8 clamp screw | G7: 1.245 | H7: Stop collar: bought 2-inch stainless clamp collar
A8: AS3-114 | B8: Stop buffer ring (EPDM) | C8: 2 | D8: part | E8: EPDM | F8: Moulded EPDM 70 ShA | G8: 0.099 | H8: Stop buffer ring, EPDM
A9: AS3-201 | B9: Pontoon hull (rotomoulded, foam filled) | C9: 2 | D9: part | E9: Rotomoulded PE, RAL 1003 signal yellow | F9: Rotomoulded PE, one mould for both hulls; PU foam fill; moulded-in M8 inserts | G9: 6.821 | H9: Pontoon hull, foam filled (prototype: welded PE sheet; production: rotomoulded LLDPE)
A10: AS3-202 | B10: Bow bumper pad | C10: 2 | D10: part | E10: EPDM | F10: Moulded EPDM, bonded | G10: 0.075 | H10: Bow bumper pad, EPDM
A11: AS3-203 | B11: Hull vent / test plug | C11: 2 | D11: purchased | E11: Acetal (POM) black | F11: Purchased PE threaded plug | G11: 0.012 | H11: Hull vent / test plug
A12: AS3-211 | B12: Crossbeam SHS 40x40x3 | C12: 4 | D12: part | E12: Aluminium 6061-T6, anodised | F12: Saw-cut 6061-T6 SHS, drilled for M8 | G12: 0.871 | H12: Crossbeam SHS 40x40x3
A13: AS3-212 | B13: Beam end cap | C13: 8 | D13: purchased | E13: Acetal (POM) black | F13: Purchased PE plug | G13: 0.009 | H13: Beam end cap
A14: AS3-213 | B14: Equipment deck plate | C14: 1 | D14: part | E14: Aluminium 6061-T6, anodised | F14: Laser-cut 3 mm 6061 tread plate | G14: 1.99 | H14: Equipment deck plate
A15: AS3-301 | B15: Guide carriage - fixed half (weldment) | C15: 1 | D15: part | E15: Aluminium 6061-T6, anodised | F15: Laser-cut 6061 plate 5/6 mm, TIG welded, hard anodised; nylon isolation at 316 axles | G15: 2.806 | H15: Guide carriage - fixed half (weldment)
A16: AS3-302 | B16: Guide carriage - opening gate (weldment) | C16: 1 | D16: part | E16: Aluminium 6061-T6, anodised | F16: Laser-cut 6061 plate, TIG welded, hard anodised | G16: 1.914 | H16: Guide carriage - opening gate (weldment)
A17: AS3-311 | B17: Concave guide roller UHMW-PE | C17: 8 | D17: part | E17: UHMW-PE | F17: CNC-turned UHMW-PE; throat profile = pole radius + 1.5 mm | G17: 0.057 | H17: Concave guide roller UHMW-PE
A18: AS3-312 | B18: Roller axle M10 + nyloc nuts | C18: 8 | D18: fastener | E18: Stainless steel 316 (brushed) | F18: 316 shoulder bolt, nylon isolation washers | G18: 0.065 | H18: Roller axle M10 shoulder bolt + nyloc
... A41: AS3-513 | B41: Pod mounting plate | C41: 1 | D41: part | E41: Aluminium 6061-T6, anodised | F41: 2 mm 5052 plate | G41: 0.358 | H41: Pod mounting plate
A42: AS3-514 | B42: LiFePO4 12.8 V 6 Ah with BMS | C42: 1 | D42: purchased | E42: LiFePO4 pack | G42: 0.8 | H42: LiFePO4 12.8 V 6 Ah with BMS
A43: AS3-515 | B43: Controller board (ESP32, RS485, RTC, microSD, LTE Cat-1) | C43: 1 | D43: purchased | E43: PCB | G43: 0.2 | H43: ESP32-WROOM-32E (DevKitC for the prototype); LTE Cat-1 modem SIMCom A7670C (on carrier board); RS485 transceiver MAX3485; Real-time clock DS3231 module; Power monitor INA226 module; PWM driver PCA9685 module (beacon, wiper, valve); microSD socket + 16 GB industrial card; Buck converters 3.3 V / 4.0 V / 5 V; MOSFET load switches, TVS, fuse, connectors, passives; Carrier PCB, 2-layer (5 boards incl. shipping)
A44: AS3-516 | B44: MPPT charge controller | C44: 1 | D44: purchased | E44: Polycarbonate dark grey | G44: 0.15 | H44: MPPT solar charger CN3791 (set to 14.4 V for LiFePO4); Battery fuse, holder and isolator
A45: AS3-521 | B45: PV module 20 W (frame + backsheet) | C45: 1 | D45: purchased | E45: Aluminium 6061-T6, anodised | G45: 1.55 | H45: Solar panel 20 W, 12 V
A46: AS3-522 | B46: PV module 20 W (cells + glass) | C46: 1 | D46: purchased | E46: Mono-Si PV cells + glass | G46: 0.45 | H46: part of the bought 20 W panel (AS3-521)
A47: AS3-523 | B47: Canopy stanchions + hinge / pin blocks | C47: 1 | D47: part | E47: Aluminium 6061-T6, anodised | F47: 6061 tube 20 x 2, welded base plates; aft pair hinged, front pair quick-release pins | G47: 0.512 | H47: Canopy stanchions + hinge / pin blocks
A48: AS3-601 | B48: Autosampler cassette (insulated body) | C48: 1 | D48: part | E48: PE white | F48: Twin-wall rotomoulded PE, PU insulated | G48: 1.904 | H48: Insulated sampler cassette + lid (bought cool box, modified)
A49: AS3-602 | B49: Autosampler lid (hinged, tamper-seal hasp) | C49: 1 | D49: part | E49: Polycarbonate dark grey | F49: Moulded PC, EPDM gasket | G49: 0.445 | H49: part of the sampler cassette (AS3-601)
A50: AS3-603 | B50: Bottle carousel (lift-out cassette) | C50: 1 | D50: part | E50: Acetal (POM) black | F50: Machined acetal; the whole carousel swaps out (chain of custody) | G50: 0.199 | H50: Carousel drive: N20 12 V gear motor; Carousel index sensor (optical slot) + bearing; Bottle carousel (lift-out cassette)
A51: AS3-604 | B51: Sample bottle 250 mL HDPE (lab-supplied) | C51: 4 | D51: purchased | E51: PE white | G51: 0.29 | H51: Sample bottles, 250 mL HDPE wide mouth
A52: AS3-605 | B52: Bottle cap (septum) | C52: 4 | D52: purchased | E52: pH ID band (blue) | G52: 0.005 | H52: Septum caps
A53: AS3-606 | B53: Peristaltic pump 12 V (reversible) | C53: 1 | D53: purchased | E53: Polycarbonate dark grey | G53: 0.35 | H53: Peristaltic pump 12 V, 260 mL/min (Kamoer KPHM200); Solenoid valves 12 V (sample / purge-to-waste)
A54: AS3-701 | B54: Beacon mast | C54: 1 | D54: part | E54: Aluminium 6061-T6, anodised | F54: 6061 tube 32 x 2.5, welded flange | G54: 0.366 | H54: Beacon mast
A55: AS3-702 | B55: Jal-Deep beacon base | C55: 1 | D55: purchased | E55: Polycarbonate dark grey | G55: 0.18 | H55: part of the beacon (AS3-703)
A56: AS3-703 | B56: Jal-Deep 360 deg LED lens (green normal / red alert) | C56: 1 | D56: purchased | E56: PC lens (green = normal) | G56: 0.08 | H56: Beacon: 12 V waterproof LED strobes, green + red
A57: AS3-711 | B57: LTE antenna (whip, N-type) | C57: 1 | D57: purchased | E57: Acetal (POM) black | G57: 0.12 | H57: 4G LTE antenna + IP67 bulkhead pigtail
A58: AS3-712 | B58: Stage sensor (waterproof ultrasonic, looking up) | C58: 1 | D58: purchased | E58: Acetal (POM) black | G58: 0.06 | H58: River-level sensor JSN-SR04T (waterproof ultrasonic)
A59: AS3-801 | B59: Grab handle (two-person carry) | C59: 4 | D59: part | E59: Stainless steel 316 (brushed) | F59: 316 tube 22 x 1.5 bent, welded pads, into hull inserts | G59: 0.23 | H59: Grab handle (two-person carry)
A60: AS3-802 | B60: Lifting eye bolt M12 (DIN 580) | C60: 4 | D60: fastener | E60: Stainless steel 316L | G60: 0.101 | H60: Lifting eye bolt M12 DIN 580
A61: AS3-811 | B61: Cable harness (probes, stage sensor, PV, beacon) | C61: 1 | D61: harness | E61: Marine cable | F61: Marine cable, IP68 glands, drip loops | G61: 0.6 | H61: IP68 cable glands M16; Marine cable harness (15 m) + connectors
A62: AS3-812 | B62: Sampler hoses (intake + purge-to-waste) | C62: 1 | D62: harness | E62: Clear PVC tubing | F62: 6 mm ID food-grade tubing | G62: 0.15 | H62: Food-grade tubing (intake, purge)
...

Sheet Business model
A1: Item | B1: Value | C1: Basis
A2: Production cost per float + bridge kit (100 units) | B2: ='Costed BOM'!H86 -> 148053.63 | C2: Costed BOM
A3: Hardware life (years) | B3: 5 | C3: ASSUMPTION
A4: Hardware, per year | B4: =B2/B3 -> 29610.727
A5: Installation, per year (₹15,000 once) | B5: 3000 | C5: ASSUMPTION
A6: Monthly service visit x 12 | B6: 18000 | C6: ASSUMPTION: ₹1,500 a visit, local technician
A7: Consumables (pH probe every ~2 years, buffers, wiper pads) | B7: 9000 | C7: ASSUMPTION
A8: LTE data | B8: 2400 | C8: ASSUMPTION: ₹200 a month M2M SIM
A9: Cloud dashboard and alerts | B9: 1200 | C9: ASSUMPTION
A10: Lab analysis, 4 event samples a year | B10: 14000 | C10: S36: ₹3,500 a sample package
A11: Cost to serve one float for a year | B11: =SUM(B4:B10) -> 77210.727
A12: Service fee per float per year | B12: 144000 | C12: PROPOSAL: ₹12,000 a month, 3-year contract
A13: Gross margin, service | B13: =1-B11/B12 -> 0.4638144
A14: Outright price per float, installed | B14: 300000 | C14: PROPOSAL
A15: Gross margin, outright sale | B15: =1-(B2+15000)/B14 -> 0.45648789 | C15: production cost + installation
A16: Annual maintenance contract | B16: 36000 | C16: PROPOSAL: 12 % of price
A17: Delhi real-time station, cost each | B17: 6875000 | C17: S37: ₹22 crore for 32 stations incl. 5 years O&M
A18: Float-years of service for one station-year | B18: =B17/5/B12 -> 9.5486111
A20: TAM: one float per CPCB monitoring location | B20: 4922 | C20: S40: 4,922 locations
A21: TAM, ₹ a year | B21: =B20*B12 -> 708768000
A22: SAM: 3 floats on each of India's 311 polluted stretches | B22: 933 | C22: S39; 3 per stretch is an ASSUMPTION
A23: SAM, ₹ a year | B23: =B22*B12 -> 134352000
A24: SOM: 3 floats on each of Maharashtra's 55 stretches | B24: 165 | C24: S39
A25: SOM, ₹ a year | B25: =B24*B12 -> 23760000
A27: Roll-out plan (PROPOSAL) | B27: Floats in service | C27: Recurring revenue, ₹ a year
A28: Year 1 | B28: 3 | C28: =B28*$B$12 -> 432000
A29: Year 2 | B29: 15 | C29: =B29*$B$12 -> 2160000
A30: Year 3 | B30: 50 | C30: =B30*$B$12 -> 7200000
A31: Year 4 | B31: 100 | C31: =B31*$B$12 -> 14400000
A32: Year 5 | B32: 165 | C32: =B32*$B$12 -> 23760000
A34: Pilot budget (the ask) | B34: ₹
A35: 3 floats + bridge kits at prototype cost | B35: 560130
A36: Lab validation: 60 samples at Rs 3,500 (S36) | B36: 210000
A37: Installation at 3 sites | B37: 45000
A38: 6 months of field service and data | B38: 32400
A39: Contingency 10 % | B39: 84753
A40: Total | B40: =SUM(B35:B39) -> 932283

Sheet Rates & assumptions
A1: Input | B1: Value | C1: Basis / source
A2: Material rate: ss_pipe | B2: 437.5 | C2: ₹/kg ex-GST, see Sources
A3: Material rate: ss_plate | B3: 315 | C3: ₹/kg ex-GST, see Sources
A4: Material rate: ss_bar | B4: 437.5 | C4: ₹/kg ex-GST, see Sources
A5: Material rate: al | B5: 375 | C5: ₹/kg ex-GST, see Sources
A6: Material rate: lldpe | B6: 117.5 | C6: ₹/kg ex-GST, see Sources
A7: Material rate: uhmw | B7: 380 | C7: ₹/kg ex-GST, see Sources
A8: Material rate: pe_sheet | B8: 295 | C8: ₹/kg ex-GST, see Sources
A9: Material rate: pom | B9: 365 | C9: ₹/kg ex-GST, see Sources
A10: Material rate: pu_foam | B10: 252.5 | C10: ₹/kg ex-GST, see Sources
A11: Shop rate: laser_m | B11: 500 | C11: ₹ ex-GST, see Sources
A12: Shop rate: tig_h | B12: 700 | C12: ₹ ex-GST, see Sources
A13: Shop rate: cnc_h | B13: 450 | C13: ₹ ex-GST, see Sources
... A16: Shop rate: hard_anod_sqft | B16: 216 | C16: ₹ ex-GST, see Sources
A17: USD to INR | B17: 96
A18: GST | B18: 0.18
A19: Probe discount at 100 units (ASSUMPTION) | B19: 0.15
A20: Labour reduction with jigs at 100 units (ASSUMPTION) | B20: 0.4
A21: Bulk material discount at 100 units (ASSUMPTION) | B21: 0.05
A22: Freight and packaging (ASSUMPTION) | B22: 0.03
A23: Contingency, prototype (ASSUMPTION) | B23: 0
A24: Contingency, at volume (ASSUMPTION) | B24: 0
A25: Rotomould tool, both hulls (ASSUMPTION within S28 range) | B25: 75000
A26: Welding and drilling jigs (ASSUMPTION) | B26: 50000
A27: Rotomoulding conversion, ₹/kg (ASSUMPTION) | B27: 80
A28: Passivation, ₹/kg (ASSUMPTION) | B28: 40
A29: Production batch for the 'at scale' column | B29: 100
A31: Basis labels: LISTED = a price found in an Indian or manufacturer listing on 23 Oct 2026; DERIVED = computed from listed rates; ASSUMPTION = an engineering estimate, to be replaced by a quote. Blue numbers are inputs.

Sheet Sources
A1: Id | B1: What it says | C1: Link
A2: S1 | B2: DFRobot store: SEN0708 RS485 pH sensor $129, SEN0680 RS485 fluorescence DO sensor $199 | C2: https://www.dfrobot.com/search-RS485.html
A3: S2 | B3: DFRobot store: SEN0707 RS485 EC sensor K=10 $159 (SEN0706 K=1 $149) | C3: https://www.dfrobot.com/search-conductivity.html
A4: S3 | B4: DFRobot store: SEN0710 RS485 turbidity sensor 0-1000 NTU $229 | C4: https://www.dfrobot.com/search-water%20quality%20monitor.html
A5: S4 | B5: Evelta (Mumbai): DFRobot SEN0706 Rs 14,414.40 and SEN0709 Rs 17,160 ex-GST, i.e. about Rs 96-97 per USD | C5: https://evelta.com/sensors/liquid-sensors/
A6: S5 | B6: Pluang currency page: USD/INR 96.5 (50-day average 95.2) | C6: https://pluang.com/en/tools/currency-converter/usd-inr
A7: S6 | B7: IndiaMART: Embsys RS485 optical DO sensor Rs 40,000; RS485 turbidity sensor Rs 38,350 ex-tax (Indian alternatives cost more) | C7: https://m.indiamart.com/proddetail/dissolved-oxygen-sensor-with-rs485-output-for-fresh-water-26441477897.html
A8: S7 | B8: Hubtronics: JSN-SR04T-2.0 waterproof ultrasonic Rs 265.25 + GST | C8: https://hubtronics.in/generic/jsn-sr04t-2.0-ultrasonic-sensor
A9: S8 | B9: IndiaMART: Espressif ESP32-DevKitC-32E Rs 749 | C9: https://m.indiamart.com/proddetail/espressif-esp32-devkitc-32e-esp32-wroom-32e-development-board-module-for-arduino-2851448645591.html
A10: S9 | B10: IndiaMART: SIMCom A7670C LTE Cat-1 module Rs 450-900 (A7670C-LNNV Rs 489); with carrier board Rs 1,900 | C10: https://m.indiamart.com/proddetail/simcom-a7670c-lnnv-lte-cat-1-module-2855267080891.html
A11: S10 | B11: Robogears: LiFePO4 12.8 V 6 Ah with BMS Rs 2,200 incl. tax; IndiaMART 12.8 V 6 Ah Rs 660-1,300 | C11: https://robogearsin.odoo.com/shop/10258578-lithium-ferrous-phosphate-lifepo4-battery-of-12-8v-6000mah-with-inbuilt-bms-for-12v-solar-ev-applicat-3642
A12: S11 | B12: Loom Solar 20 W 12 V panel Rs 1,299 (Amazon-fulfilled listing, regular Rs 2,500) | C12: https://www.ysvara.com/products/loom-solar-panel-20w-12v-for-home-lighting-system-diy-projects-small-battery-charging7ah-pack-of-1-max-current-1-04-amps-max-voltage-19-25-volts-performance-warranty-25-years
... A50: S49 | B50: Previous team cost sheet (v2 layout): hardware/AquaSentinel_Cost_Estimate_BOM.csv, lines sum to Rs 1,38,000 incl. GST | C50: hardware/AquaSentinel_Cost_Estimate_BOM.csv
B52: All prices looked up on 23 Oct 2026. Listings change; confirm with a written quote before ordering.
